Traceback (most recent call last):
  File "ILPimplementation/main.py", line 124, in <module>
    partial_x = load_partial_solution(partial_x_file)
  File "ILPimplementation/main.py", line 19, in load_partial_solution
    partial_solution = pd.read_csv(file_path)
  File "/usr/local/python/3.8.2/lib/python3.8/site-packages/pandas/io/parsers.py", line 676, in parser_f
    return _read(filepath_or_buffer, kwds)
  File "/usr/local/python/3.8.2/lib/python3.8/site-packages/pandas/io/parsers.py", line 448, in _read
    parser = TextFileReader(fp_or_buf, **kwds)
  File "/usr/local/python/3.8.2/lib/python3.8/site-packages/pandas/io/parsers.py", line 880, in __init__
    self._make_engine(self.engine)
  File "/usr/local/python/3.8.2/lib/python3.8/site-packages/pandas/io/parsers.py", line 1114, in _make_engine
    self._engine = CParserWrapper(self.f, **self.options)
  File "/usr/local/python/3.8.2/lib/python3.8/site-packages/pandas/io/parsers.py", line 1891, in __init__
    self._reader = parsers.TextReader(src, **kwds)
  File "pandas/_libs/parsers.pyx", line 374, in pandas._libs.parsers.TextReader.__cinit__
  File "pandas/_libs/parsers.pyx", line 674, in pandas._libs.parsers.TextReader._setup_parser_source
FileNotFoundError: [Errno 2] File ILPimplementation/output_files/version5.1/6htest_new_cyclelines_x_ld_results.csv does not exist: 'ILPimplementation/output_files/version5.1/6htest_new_cyclelines_x_ld_results.csv'
